Workbook

Sheet Issues
A1: Ticket ID | B1: GH # | C1: Title | D1: Module | E1: Epic | F1: Priority | G1: Phase | H1: Size | I1: Est. days | J1: Cut | K1: Area | L1: Status | M1: Assignees | N1: State | O1: Blocked by | P1: Open blockers | Q1: Link
A2: ADM-L01 | B2: 205 | C2: [ADMIN] Build the platform admin console | D2: admin | E2: [EPIC] M18 · Platform Admin & Billing | F2: — | G2: Later | H2: L | I2: =IF(H2="S",0.5,IF(H2="M",1,IF(H2="L",2,0))) | J2: Later | K2: backend | L2: Accepted | N2: OPEN | O2: IDN-006 | P2: =IF(O2="",0,SUMPRODUCT(--ISNUMBER(SEARCH(", "&$A$2:$A$245&",",", "&O2&",")),--($L$2:$L$245<>"Done"))) | Q2: open
A3: ADM-L02 | B3: 206 | C3: [ADMIN] Meter usage for billing | D3: admin | E3: [EPIC] M18 · Platform Admin & Billing | F3: — | G3: Later | H3: M | I3: =IF(H3="S",0.5,IF(H3="M",1,IF(H3="L",2,0))) | J3: Later | K3: backend | L3: Accepted | N3: OPEN | O3: OBS-004 | P3: =IF(O3="",0,SUMPRODUCT(--ISNUMBER(SEARCH(", "&$A$2:$A$245&",",", "&O3&",")),--($L$2:$L$245<>"Done"))) | Q3: open
A4: ADM-L03 | B4: 207 | C4: [ADMIN] Add subscriptions and customer invoicing | D4: admin | E4: [EPIC] M18 · Platform Admin & Billing | F4: — | G4: Later | H4: L | I4: =IF(H4="S",0.5,IF(H4="M",1,IF(H4="L",2,0))) | J4: Later | K4: backend | L4: Accepted | N4: OPEN | O4: ADM-L02 | P4: =IF(O4="",0,SUMPRODUCT(--ISNUMBER(SEARCH(", "&$A$2:$A$245&",",", "&O4&",")),--($L$2:$L$245<>"Done"))) | Q4: open
A5: AGT-001 | B5: 132 | C5: [AGENT] Build the LLM adapter with routing and timeouts | D5: agent | E5: [EPIC] M09 · AI Agent | F5: P0 | G5: M1 | H5: M | I5: =IF(H5="S",0.5,IF(H5="M",1,IF(H5="L",2,0))) | J5: A | K5: ai | L5: Assigned | M5: therealtunguyen | N5: OPEN | O5: EXE-002 | P5: =IF(O5="",0,SUMPRODUCT(--ISNUMBER(SEARCH(", "&$A$2:$A$245&",",", "&O5&",")),--($L$2:$L$245<>"Done"))) | Q5: open
A6: AGT-002 | B6: 134 | C6: [AGENT] Log every AI call and fail closed | D6: agent | E6: [EPIC] M09 · AI Agent | F6: P0 | G6: M1 | H6: S | I6: =IF(H6="S",0.5,IF(H6="M",1,IF(H6="L",2,0))) | J6: A | K6: ai | L6: Assigned | M6: therealtunguyen | N6: OPEN | O6: AGT-001 | P6: =IF(O6="",0,SUMPRODUCT(--ISNUMBER(SEARCH(", "&$A$2:$A$245&",",", "&O6&",")),--($L$2:$L$245<>"Done"))) | Q6: open
A7: AGT-003 | B7: 133 | C7: [AGENT] Implement untrusted-content wrapping and sanitization | D7: agent | E7: [EPIC] M09 · AI Agent | F7: P0 | G7: M1 | H7: S | I7: =IF(H7="S",0.5,IF(H7="M",1,IF(H7="L",2,0))) | J7: A | K7: ai | L7: Assigned | M7: therealtunguyen | N7: OPEN | O7: AGT-001 | P7: =IF(O7="",0,SUMPRODUCT(--ISNUMBER(SEARCH(", "&$A$2:$A$245&",",", "&O7&",")),--($L$2:$L$245<>"Done"))) | Q7: open
A8: AGT-004 | B8: 135 | C8: [AGENT] Implement invoice extraction | D8: agent | E8: [EPIC] M09 · AI Agent | F8: P0 | G8: M1 | H8: M | I8: =IF(H8="S",0.5,IF(H8="M",1,IF(H8="L",2,0))) | J8: A | K8: ai | L8: Assigned | M8: therealtunguyen | N8: OPEN | O8: AGT-003, AGT-002, INV-004 | P8: =IF(O8="",0,SUMPRODUCT(--ISNUMBER(SEARCH(", "&$A$2:$A$245&",",", "&O8&",")),--($L$2:$L$245<>"Done"))) | Q8: open
A9: AGT-005 | B9: 170 | C9: [AGENT] Extract and validate payment terms | D9: agent | E9: [EPIC] M09 · AI Agent | F9: P0 | G9: M1 | H9: S | I9: =IF(H9="S",0.5,IF(H9="M",1,IF(H9="L",2,0))) | J9: A | K9: ai | L9: Assigned | M9: therealtunguyen | N9: OPEN | O9: AGT-004, ENG-005 | P9: =IF(O9="",0,SUMPRODUCT(--ISNUMBER(SEARCH(", "&$A$2:$A$245&",",", "&O9&",")),--($L$2:$L$245<>"Done"))) | Q9: open
A10: AGT-006 | B10: 171 | C10: [AGENT] Detect instruction-like text in documents | D10: agent | E10: [EPIC] M09 · AI Agent | F10: P0 | G10: M1 | H10: S | I10: =IF(H10="S",0.5,IF(H10="M",1,IF(H10="L",2,0))) | J10: A | K10: ai | L10: Assigned | M10: therealtunguyen | N10: OPEN | O10: AGT-004 | P10: =IF(O10="",0,SUMPRODUCT(--ISNUMBER(SEARCH(", "&$A$2:$A$245&",",", "&O10&",")),--($L$2:$L$245<>"Done"))) | Q10: open
A11: AGT-007 | B11: 143 | C11: [AGENT] Implement the read-only tool layer | D11: agent | E11: [EPIC] M09 · AI Agent | F11: P0 | G11: M1 | H11: M | I11: =IF(H11="S",0.5,IF(H11="M",1,IF(H11="L",2,0))) | J11: A | K11: ai | L11: Assigned | M11: therealtunguyen | N11: OPEN | O11: CHR-002, ENG-008, POL-003 | P11: =IF(O11="",0,SUMPRODUCT(--ISNUMBER(SEARCH(", "&$A$2:$A$245&",",", "&O11&",")),--($L$2:$L$245<>"Done"))) | Q11: open
A12: AGT-008 | B12: 144 | C12: [AGENT] Implement the plan proposer | D12: agent | E12: [EPIC] M09 · AI Agent | F12: P0 | G12: M1 | H12: M | I12: =IF(H12="S",0.5,IF(H12="M",1,IF(H12="L",2,0))) | J12: A | K12: ai | L12: Assigned | M12: therealtunguyen | N12: OPEN | O12: AGT-007 | P12: =IF(O12="",0,SUMPRODUCT(--ISNUMBER(SEARCH(", "&$A$2:$A$245&",",", "&O12&",")),--($L$2:$L$245<>"Done"))) | Q12: open
A13: AGT-009 | B13: 145 | C13: [AGENT] Score AI proposals and select the plan | D13: agent | E13: [EPIC] M09 · AI Agent | F13: P0 | G13: M1 | H13: S | I13: =IF(H13="S",0.5,IF(H13="M",1,IF(H13="L",2,0))) | J13: A | K13: ai | L13: Assigned | M13: therealtunguyen | N13: OPEN | O13: AGT-008, ENG-008 | P13: =IF(O13="",0,SUMPRODUCT(--ISNUMBER(SEARCH(", "&$A$2:$A$245&",",", "&O13&",")),--($L$2:$L$245<>"Done"))) | Q13: open
A14: AGT-010 | B14: 172 | C14: [AGENT] Implement rule-based fallback templates | D14: agent | E14: [EPIC] M09 · AI Agent | F14: P0 | G14: M1 | H14: S | I14: =IF(H14="S",0.5,IF(H14="M",1,IF(H14="L",2,0))) | J14: A | K14: ai | L14: Assigned | M14: therealtunguyen | N14: OPEN | O14: ENG-007, POL-003 | P14: =IF(O14="",0,SUMPRODUCT(--ISNUMBER(SEARCH(", "&$A$2:$A$245&",",", "&O14&",")),--($L$2:$L$245<>"Done"))) | Q14: open
A15: AGT-011 | B15: 173 | C15: [AGENT] Draft exception requests with a numeric post-check | D15: agent | E15: [EPIC] M09 · AI Agent | F15: P1 | G15: M1 | H15: S | I15: =IF(H15="S",0.5,IF(H15="M",1,IF(H15="L",2,0))) | J15: B | K15: ai | L15: Assigned | M15: therealtunguyen | N15: OPEN | O15: AGT-001, MDT-006 | P15: =IF(O15="",0,SUMPRODUCT(--ISNUMBER(SEARCH(", "&$A$2:$A$245&",",", "&O15&",")),--($L$2:$L$245<>"Done"))) | Q15: open
A16: AGT-012 | B16: 174 | C16: [AGENT] Build the Copilot backend | D16: agent | E16: [EPIC] M09 · AI Agent | F16: P1 | G16: M1 | H16: L | I16: =IF(H16="S",0.5,IF(H16="M",1,IF(H16="L",2,0))) | J16: After submission | K16: ai | L16: Assigned | M16: therealtunguyen | N16: OPEN | O16: AGT-007 | P16: =IF(O16="",0,SUMPRODUCT(--ISNUMBER(SEARCH(", "&$A$2:$A$245&",",", "&O16&",")),--($L$2:$L$245<>"Done"))) | Q16: open
... A25: AUD-004 | B25: 198 | C25: [AUDIT] Propagate coverage labels through the API | D25: audit | E25: [EPIC] M15 · Audit & Evidence | F25: P1 | G25: M1 | H25: S | I25: =IF(H25="S",0.5,IF(H25="M",1,IF(H25="L",2,0))) | J25: After submission | K25: backend | L25: Assigned | M25: Nostidus4 | N25: OPEN | O25: CHR-002 | P25: =IF(O25="",0,SUMPRODUCT(--ISNUMBER(SEARCH(", "&$A$2:$A$245&",",", "&O25&",")),--($L$2:$L$245<>"Done"))) | Q25: open
A26: AUD-L01 | B26: 199 | C26: [AUDIT] Anchor the audit hash root on-chain daily | D26: audit | E26: [EPIC] M15 · Audit & Evidence | F26: — | G26: Later | H26: S | I26: =IF(H26="S",0.5,IF(H26="M",1,IF(H26="L",2,0))) | J26: Later | K26: backend | L26: Accepted | N26: OPEN | O26: AUD-002 | P26: =IF(O26="",0,SUMPRODUCT(--ISNUMBER(SEARCH(", "&$A$2:$A$245&",",", "&O26&",")),--($L$2:$L$245<>"Done"))) | Q26: open
A27: CHR-001 | B27: 35 | C27: [CHAIN] Build the RPC client with failover | D27: chain-reader | E27: [EPIC] M06 · Chain Reader & Tx Tracking | F27: P0 | G27: M1 | H27: M | I27: =IF(H27="S",0.5,IF(H27="M",1,IF(H27="L",2,0))) | J27: A | K27: backend | L27: Assigned | M27: Nostidus4 | N27: OPEN | O27: TRS-002 | P27: =IF(O27="",0,SUMPRODUCT(--ISNUMBER(SEARCH(", "&$A$2:$A$245&",",", "&O27&",")),--($L$2:$L$245<>"Done"))) | Q27: open
A28: CHR-002 | B28: 140 | C28: [CHAIN] Implement block-consistent snapshots | D28: chain-reader | E28: [EPIC] M06 · Chain Reader & Tx Tracking | F28: P0 | G28: M1 | H28: M | I28: =IF(H28="S",0.5,IF(H28="M",1,IF(H28="L",2,0))) | J28: A | K28: backend | L28: Assigned | M28: Nostidus4 | N28: OPEN | O28: CHR-001, TRS-004 | P28: =IF(O28="",0,SUMPRODUCT(--ISNUMBER(SEARCH(", "&$A$2:$A$245&",",", "&O28&",")),--($L$2:$L$245<>"Done"))) | Q28: open
A29: CHR-003 | B29: 47 | C29: [CHAIN] Implement the transaction tracker | D29: chain-reader | E29: [EPIC] M06 · Chain Reader & Tx Tracking | F29: P0 | G29: M1 | H29: M | I29: =IF(H29="S",0.5,IF(H29="M",1,IF(H29="L",2,0))) | J29: A | K29: backend | L29: Assigned | M29: Nostidus4 | N29: OPEN | O29: CHR-001, EXE-001 | P29: =IF(O29="",0,SUMPRODUCT(--ISNUMBER(SEARCH(", "&$A$2:$A$245&",",", "&O29&",")),--($L$2:$L$245<>"Done"))) | Q29: open
A30: CHR-004 | B30: 141 | C30: [CHAIN] Detect reorgs and re-evaluate status | D30: chain-reader | E30: [EPIC] M06 · Chain Reader & Tx Tracking | F30: P1 | G30: M1 | H30: S | I30: =IF(H30="S",0.5,IF(H30="M",1,IF(H30="L",2,0))) | J30: After submission | K30: backend | L30: Assigned | M30: Nostidus4 | N30: OPEN | O30: CHR-003 | P30: =IF(O30="",0,SUMPRODUCT(--ISNUMBER(SEARCH(", "&$A$2:$A$245&",",", "&O30&",")),--($L$2:$L$245<>"Done"))) | Q30: open
A31: CHR-005 | B31: 117 | C31: [CHAIN] Index module and Safe events | D31: chain-reader | E31: [EPIC] M06 · Chain Reader & Tx Tracking | F31: P1 | G31: M1 | H31: M | I31: =IF(H31="S",0.5,IF(H31="M",1,IF(H31="L",2,0))) | J31: A | K31: backend | L31: Assigned | M31: Nostidus4 | N31: OPEN | O31: CHR-001, SC-016 | P31: =IF(O31="",0,SUMPRODUCT(--ISNUMBER(SEARCH(", "&$A$2:$A$245&",",", "&O31&",")),--($L$2:$L$245<>"Done"))) | Q31: open
A32: CHR-006 | B32: 253 | C32: [CHAIN] Index treasury token movements and alert on unexpected outflows | D32: chain-reader | E32: [EPIC] M06 · Chain Reader & Tx Tracking | F32: P0 | G32: M1 | H32: S | I32: =IF(H32="S",0.5,IF(H32="M",1,IF(H32="L",2,0))) | J32: A | K32: backend | L32: Assigned | M32: Nostidus4 | N32: OPEN | O32: CHR-005, EXE-001 | P32: =IF(O32="",0,SUMPRODUCT(--ISNUMBER(SEARCH(", "&$A$2:$A$245&",",", "&O32&",")),--($L$2:$L$245<>"Done"))) | Q32: open
A33: CMP-001 | B33: 50 | C33: [COMPLIANCE] Build the screening adapter and fixture provider | D33: compliance | E33: [EPIC] M14 · Compliance | F33: P1 | G33: M1 | H33: S | I33: =IF(H33="S",0.5,IF(H33="M",1,IF(H33="L",2,0))) | J33: A | K33: backend | L33: Assigned | M33: Nostidus4 | N33: OPEN | O33: MDT-001 | P33: =IF(O33="",0,SUMPRODUCT(--ISNUMBER(SEARCH(", "&$A$2:$A$245&",",", "&O33&",")),--($L$2:$L$245<>"Done"))) | Q33: open
A34: CMP-002 | B34: 191 | C34: [COMPLIANCE] Screen payees before each PAY | D34: compliance | E34: [EPIC] M14 · Compliance | F34: P1 | G34: M1 | H34: S | I34: =IF(H34="S",0.5,IF(H34="M",1,IF(H34="L",2,0))) | J34: After submission | K34: backend | L34: Assigned | M34: Nostidus4 | N34: OPEN | O34: CMP-001, POL-003 | P34: =IF(O34="",0,SUMPRODUCT(--ISNUMBER(SEARCH(", "&$A$2:$A$245&",",", "&O34&",")),--($L$2:$L$245<>"Done"))) | Q34: open
A35: CMP-003 | B35: 192 | C35: [COMPLIANCE] Implement data classification, encryption helpers and log redaction | D35: compliance | E35: [EPIC] M14 · Compliance | F35: P0 | G35: M1 | H35: M | I35: =IF(H35="S",0.5,IF(H35="M",1,IF(H35="L",2,0))) | J35: B | K35: backend | L35: Assigned | M35: Nostidus4 | N35: OPEN | O35: DEV-001 | P35: =IF(O35="",0,SUMPRODUCT(--ISNUMBER(SEARCH(", "&$A$2:$A$245&",",", "&O35&",")),--($L$2:$L$245<>"Done"))) | Q35: open
A36: CMP-L01 | B36: 193 | C36: [COMPLIANCE] Integrate a KYB provider | D36: compliance | E36: [EPIC] M14 · Compliance | F36: — | G36: Later | H36: L | I36: =IF(H36="S",0.5,IF(H36="M",1,IF(H36="L",2,0))) | J36: Later | K36: backend | L36: Accepted | N36: OPEN | O36: CMP-001 | P36: =IF(O36="",0,SUMPRODUCT(--ISNUMBER(SEARCH(", "&$A$2:$A$245&",",", "&O36&",")),--($L$2:$L$245<>"Done"))) | Q36: open
A37: CMP-L02 | B37: 194 | C37: [COMPLIANCE] Add Travel Rule support | D37: compliance | E37: [EPIC] M14 · Compliance | F37: — | G37: Later | H37: L | I37: =IF(H37="S",0.5,IF(H37="M",1,IF(H37="L",2,0))) | J37: Later | K37: backend | L37: Accepted | N37: OPEN | O37: CMP-L01 | P37: =IF(O37="",0,SUMPRODUCT(--ISNUMBER(SEARCH(", "&$A$2:$A$245&",",", "&O37&",")),--($L$2:$L$245<>"Done"))) | Q37: open
A38: CMP-L03 | B38: 195 | C38: [COMPLIANCE] Add retention and deletion workflows | D38: compliance | E38: [EPIC] M14 · Compliance | F38: — | G38: Later | H38: M | I38: =IF(H38="S",0.5,IF(H38="M",1,IF(H38="L",2,0))) | J38: Later | K38: backend | L38: Accepted | N38: OPEN | O38: CMP-003 | P38: =IF(O38="",0,SUMPRODUCT(--ISNUMBER(SEARCH(", "&$A$2:$A$245&",",", "&O38&",")),--($L$2:$L$245<>"Done"))) | Q38: open
A39: CMP-L04 | B39: 196 | C39: [COMPLIANCE] Add region pinning for stored data | D39: compliance | E39: [EPIC] M14 · Compliance | F39: — | G39: Later | H39: M | I39: =IF(H39="S",0.5,IF(H39="M",1,IF(H39="L",2,0))) | J39: Later | K39: backend | L39: Accepted | N39: OPEN | O39: CMP-L03 | P39: =IF(O39="",0,SUMPRODUCT(--ISNUMBER(SEARCH(", "&$A$2:$A$245&",",", "&O39&",")),--($L$2:$L$245<>"Done"))) | Q39: open
A40: DEV-001 | B40: 21 | C40: [DEVEX] Initialize monorepo skeleton | D40: devex | E40: [EPIC] M19 · Developer Experience & Quality | F40: P0 | G40: M1 | H40: M | I40: =IF(H40="S",0.5,IF(H40="M",1,IF(H40="L",2,0))) | J40: A | K40: infrastructure | L40: Done | N40: CLOSED | P40: =IF(O40="",0,SUMPRODUCT(--ISNUMBER(SEARCH(", "&$A$2:$A$245&",",", "&O40&",")),--($L$2:$L$245<>"Done"))) | Q40: open
A41: DEV-002 | B41: 22 | C41: [DEVEX] Create Docker Compose stack (local profile) | D41: devex | E41: [EPIC] M19 · Developer Experience & Quality | F41: P0 | G41: M1 | H41: M | I41: =IF(H41="S",0.5,IF(H41="M",1,IF(H41="L",2,0))) | J41: A | K41: infrastructure | L41: Done | N41: CLOSED | O41: DEV-001 | P41: =IF(O41="",0,SUMPRODUCT(--ISNUMBER(SEARCH(", "&$A$2:$A$245&",",", "&O41&",")),--($L$2:$L$245<>"Done"))) | Q41: open
A42: DEV-003 | B42: 23 | C42: [DEVEX] Add CI workflow for Python | D42: devex | E42: [EPIC] M19 · Developer Experience & Quality | F42: P1 | G42: M1 | H42: S | I42: =IF(H42="S",0.5,IF(H42="M",1,IF(H42="L",2,0))) | J42: A | K42: infrastructure | L42: Done | N42: CLOSED | O42: DEV-001 | P42: =IF(O42="",0,SUMPRODUCT(--ISNUMBER(SEARCH(", "&$A$2:$A$245&",",", "&O42&",")),--($L$2:$L$245<>"Done"))) | Q42: open
A43: DEV-004 | B43: 25 | C43: [DEVEX] Add CI workflow for contracts | D43: devex | E43: [EPIC] M19 · Developer Experience & Quality | F43: P1 | G43: M1 | H43: S | I43: =IF(H43="S",0.5,IF(H43="M",1,IF(H43="L",2,0))) | J43: B | K43: infrastructure | L43: Assigned | M43: therealtunguyen | N43: OPEN | O43: SC-001 | P43: =IF(O43="",0,SUMPRODUCT(--ISNUMBER(SEARCH(", "&$A$2:$A$245&",",", "&O43&",")),--($L$2:$L$245<>"Done"))) | Q43: open
A44: DEV-005 | B44: 27 | C44: [DEVEX] Add CI workflow for web and OpenAPI client drift | D44: devex | E44: [EPIC] M19 · Developer Experience & Quality | F44: P1 | G44: M1 | H44: S | I44: =IF(H44="S",0.5,IF(H44="M",1,IF(H44="L",2,0))) | J44: After submission | K44: infrastructure | L44: Done | N44: CLOSED | O44: WEB-001 | P44: =IF(O44="",0,SUMPRODUCT(--ISNUMBER(SEARCH(", "&$A$2:$A$245&",",", "&O44&",")),--($L$2:$L$245<>"Done"))) | Q44: open
A45: DEV-006 | B45: 53 | C45: [DEVEX] Write seed script for the local environment | D45: devex | E45: [EPIC] M19 · Developer Experience & Quality | F45: P1 | G45: M1 | H45: M | I45: =IF(H45="S",0.5,IF(H45="M",1,IF(H45="L",2,0))) | J45: A | K45: infrastructure | L45: Assigned | M45: therealtunguyen | N45: OPEN | O45: SC-016, TRS-004, MDT-003, INV-003 | P45: =IF(O45="",0,SUMPRODUCT(--ISNUMBER(SEARCH(", "&$A$2:$A$245&",",", "&O45&",")),--($L$2:$L$245<>"Done"))) | Q45: open
A46: DEV-007 | B46: 67 | C46: [DEVEX] Build scenario runner CLI | D46: devex | E46: [EPIC] M19 · Developer Experience & Quality | F46: P1 | G46: M1 | H46: M | I46: =IF(H46="S",0.5,IF(H46="M",1,IF(H46="L",2,0))) | J46: A | K46: infrastructure | L46: Assigned | M46: therealtunguyen | N46: OPEN | O46: DEV-006, AUD-003 | P46: =IF(O46="",0,SUMPRODUCT(--ISNUMBER(SEARCH(", "&$A$2:$A$245&",",", "&O46&",")),--($L$2:$L$245<>"Done"))) | Q46: open
A47: DEV-008 | B47: 68 | C47: [DEVEX] Write the demo runbook | D47: devex | E47: [EPIC] M19 · Developer Experience & Quality | F47: P1 | G47: M1 | H47: S | I47: =IF(H47="S",0.5,IF(H47="M",1,IF(H47="L",2,0))) | J47: A | K47: infrastructure | L47: Assigned | M47: therealtunguyen | N47: OPEN | O47: DEV-007 | P47: =IF(O47="",0,SUMPRODUCT(--ISNUMBER(SEARCH(", "&$A$2:$A$245&",",", "&O47&",")),--($L$2:$L$245<>"Done"))) | Q47: open
A48: DEV-009 | B48: 69 | C48: [DEVEX] Build the reliability run harness | D48: devex | E48: [EPIC] M19 · Developer Experience & Quality | F48: P1 | G48: M1 | H48: S | I48: =IF(H48="S",0.5,IF(H48="M",1,IF(H48="L",2,0))) | J48: After submission | K48: infrastructure | L48: Assigned | M48: therealtunguyen | N48: OPEN | O48: DEV-007 | P48: =IF(O48="",0,SUMPRODUCT(--ISNUMBER(SEARCH(", "&$A$2:$A$245&",",", "&O48&",")),--($L$2:$L$245<>"Done"))) | Q48: open
...

Sheet Module Progress
A1: Module | B1: Tickets | C1: Done | D1: In Progress | E1: Review | F1: Not started | G1: % done (count) | H1: Est. days | I1: Est. days done | J1: % done (effort) | K1: Cut A tickets | L1: Cut A done | M1: % Cut A done
A2: admin | B2: =COUNTIFS(Issues!$D$2:$D$245,A2) | C2: =COUNTIFS(Issues!$D$2:$D$245,A2,Issues!$L$2:$L$245,"Done") | D2: =COUNTIFS(Issues!$D$2:$D$245,A2,Issues!$L$2:$L$245,"In Progress") | E2: =COUNTIFS(Issues!$D$2:$D$245,A2,Issues!$L$2:$L$245,"Review") | F2: =B2-C2-D2-E2 | G2: =IF(B2=0,0,C2/B2) | H2: =SUMIFS(Issues!$I$2:$I$245,Issues!$D$2:$D$245,A2) | I2: =SUMIFS(Issues!$I$2:$I$245,Issues!$D$2:$D$245,A2,Issues!$L$2:$L$245,"Done") | J2: =IF(H2=0,0,I2/H2) | K2: =COUNTIFS(Issues!$D$2:$D$245,A2,Issues!$J$2:$J$245,"A") | L2: =COUNTIFS(Issues!$D$2:$D$245,A2,Issues!$J$2:$J$245,"A",Issues!$L$2:$L$245,"Done") | M2: =IF(K2=0,0,L2/K2)
A3: agent | B3: =COUNTIFS(Issues!$D$2:$D$245,A3) | C3: =COUNTIFS(Issues!$D$2:$D$245,A3,Issues!$L$2:$L$245,"Done") | D3: =COUNTIFS(Issues!$D$2:$D$245,A3,Issues!$L$2:$L$245,"In Progress") | E3: =COUNTIFS(Issues!$D$2:$D$245,A3,Issues!$L$2:$L$245,"Review") | F3: =B3-C3-D3-E3 | G3: =IF(B3=0,0,C3/B3) | H3: =SUMIFS(Issues!$I$2:$I$245,Issues!$D$2:$D$245,A3) | I3: =SUMIFS(Issues!$I$2:$I$245,Issues!$D$2:$D$245,A3,Issues!$L$2:$L$245,"Done") | J3: =IF(H3=0,0,I3/H3) | K3: =COUNTIFS(Issues!$D$2:$D$245,A3,Issues!$J$2:$J$245,"A") | L3: =COUNTIFS(Issues!$D$2:$D$245,A3,Issues!$J$2:$J$245,"A",Issues!$L$2:$L$245,"Done") | M3: =IF(K3=0,0,L3/K3)
A4: audit | B4: =COUNTIFS(Issues!$D$2:$D$245,A4) | C4: =COUNTIFS(Issues!$D$2:$D$245,A4,Issues!$L$2:$L$245,"Done") | D4: =COUNTIFS(Issues!$D$2:$D$245,A4,Issues!$L$2:$L$245,"In Progress") | E4: =COUNTIFS(Issues!$D$2:$D$245,A4,Issues!$L$2:$L$245,"Review") | F4: =B4-C4-D4-E4 | G4: =IF(B4=0,0,C4/B4) | H4: =SUMIFS(Issues!$I$2:$I$245,Issues!$D$2:$D$245,A4) | I4: =SUMIFS(Issues!$I$2:$I$245,Issues!$D$2:$D$245,A4,Issues!$L$2:$L$245,"Done") | J4: =IF(H4=0,0,I4/H4) | K4: =COUNTIFS(Issues!$D$2:$D$245,A4,Issues!$J$2:$J$245,"A") | L4: =COUNTIFS(Issues!$D$2:$D$245,A4,Issues!$J$2:$J$245,"A",Issues!$L$2:$L$245,"Done") | M4: =IF(K4=0,0,L4/K4)
A5: chain-reader | B5: =COUNTIFS(Issues!$D$2:$D$245,A5) | C5: =COUNTIFS(Issues!$D$2:$D$245,A5,Issues!$L$2:$L$245,"Done") | D5: =COUNTIFS(Issues!$D$2:$D$245,A5,Issues!$L$2:$L$245,"In Progress") | E5: =COUNTIFS(Issues!$D$2:$D$245,A5,Issues!$L$2:$L$245,"Review") | F5: =B5-C5-D5-E5 | G5: =IF(B5=0,0,C5/B5) | H5: =SUMIFS(Issues!$I$2:$I$245,Issues!$D$2:$D$245,A5) | I5: =SUMIFS(Issues!$I$2:$I$245,Issues!$D$2:$D$245,A5,Issues!$L$2:$L$245,"Done") | J5: =IF(H5=0,0,I5/H5) | K5: =COUNTIFS(Issues!$D$2:$D$245,A5,Issues!$J$2:$J$245,"A") | L5: =COUNTIFS(Issues!$D$2:$D$245,A5,Issues!$J$2:$J$245,"A",Issues!$L$2:$L$245,"Done") | M5: =IF(K5=0,0,L5/K5)
A6: compliance | B6: =COUNTIFS(Issues!$D$2:$D$245,A6) | C6: =COUNTIFS(Issues!$D$2:$D$245,A6,Issues!$L$2:$L$245,"Done") | D6: =COUNTIFS(Issues!$D$2:$D$245,A6,Issues!$L$2:$L$245,"In Progress") | E6: =COUNTIFS(Issues!$D$2:$D$245,A6,Issues!$L$2:$L$245,"Review") | F6: =B6-C6-D6-E6 | G6: =IF(B6=0,0,C6/B6) | H6: =SUMIFS(Issues!$I$2:$I$245,Issues!$D$2:$D$245,A6) | I6: =SUMIFS(Issues!$I$2:$I$245,Issues!$D$2:$D$245,A6,Issues!$L$2:$L$245,"Done") | J6: =IF(H6=0,0,I6/H6) | K6: =COUNTIFS(Issues!$D$2:$D$245,A6,Issues!$J$2:$J$245,"A") | L6: =COUNTIFS(Issues!$D$2:$D$245,A6,Issues!$J$2:$J$245,"A",Issues!$L$2:$L$245,"Done") | M6: =IF(K6=0,0,L6/K6)
A7: contracts | B7: =COUNTIFS(Issues!$D$2:$D$245,A7) | C7: =COUNTIFS(Issues!$D$2:$D$245,A7,Issues!$L$2:$L$245,"Done") | D7: =COUNTIFS(Issues!$D$2:$D$245,A7,Issues!$L$2:$L$245,"In Progress") | E7: =COUNTIFS(Issues!$D$2:$D$245,A7,Issues!$L$2:$L$245,"Review") | F7: =B7-C7-D7-E7 | G7: =IF(B7=0,0,C7/B7) | H7: =SUMIFS(Issues!$I$2:$I$245,Issues!$D$2:$D$245,A7) | I7: =SUMIFS(Issues!$I$2:$I$245,Issues!$D$2:$D$245,A7,Issues!$L$2:$L$245,"Done") | J7: =IF(H7=0,0,I7/H7) | K7: =COUNTIFS(Issues!$D$2:$D$245,A7,Issues!$J$2:$J$245,"A") | L7: =COUNTIFS(Issues!$D$2:$D$245,A7,Issues!$J$2:$J$245,"A",Issues!$L$2:$L$245,"Done") | M7: =IF(K7=0,0,L7/K7)
A8: devex | B8: =COUNTIFS(Issues!$D$2:$D$245,A8) | C8: =COUNTIFS(Issues!$D$2:$D$245,A8,Issues!$L$2:$L$245,"Done") | D8: =COUNTIFS(Issues!$D$2:$D$245,A8,Issues!$L$2:$L$245,"In Progress") | E8: =COUNTIFS(Issues!$D$2:$D$245,A8,Issues!$L$2:$L$245,"Review") | F8: =B8-C8-D8-E8 | G8: =IF(B8=0,0,C8/B8) | H8: =SUMIFS(Issues!$I$2:$I$245,Issues!$D$2:$D$245,A8) | I8: =SUMIFS(Issues!$I$2:$I$245,Issues!$D$2:$D$245,A8,Issues!$L$2:$L$245,"Done") | J8: =IF(H8=0,0,I8/H8) | K8: =COUNTIFS(Issues!$D$2:$D$245,A8,Issues!$J$2:$J$245,"A") | L8: =COUNTIFS(Issues!$D$2:$D$245,A8,Issues!$J$2:$J$245,"A",Issues!$L$2:$L$245,"Done") | M8: =IF(K8=0,0,L8/K8)
A9: domain-evidence | B9: =COUNTIFS(Issues!$D$2:$D$245,A9) | C9: =COUNTIFS(Issues!$D$2:$D$245,A9,Issues!$L$2:$L$245,"Done") | D9: =COUNTIFS(Issues!$D$2:$D$245,A9,Issues!$L$2:$L$245,"In Progress") | E9: =COUNTIFS(Issues!$D$2:$D$245,A9,Issues!$L$2:$L$245,"Review") | F9: =B9-C9-D9-E9 | G9: =IF(B9=0,0,C9/B9) | H9: =SUMIFS(Issues!$I$2:$I$245,Issues!$D$2:$D$245,A9) | I9: =SUMIFS(Issues!$I$2:$I$245,Issues!$D$2:$D$245,A9,Issues!$L$2:$L$245,"Done") | J9: =IF(H9=0,0,I9/H9) | K9: =COUNTIFS(Issues!$D$2:$D$245,A9,Issues!$J$2:$J$245,"A") | L9: =COUNTIFS(Issues!$D$2:$D$245,A9,Issues!$J$2:$J$245,"A",Issues!$L$2:$L$245,"Done") | M9: =IF(K9=0,0,L9/K9)
A10: execution | B10: =COUNTIFS(Issues!$D$2:$D$245,A10) | C10: =COUNTIFS(Issues!$D$2:$D$245,A10,Issues!$L$2:$L$245,"Done") | D10: =COUNTIFS(Issues!$D$2:$D$245,A10,Issues!$L$2:$L$245,"In Progress") | E10: =COUNTIFS(Issues!$D$2:$D$245,A10,Issues!$L$2:$L$245,"Review") | F10: =B10-C10-D10-E10 | G10: =IF(B10=0,0,C10/B10) | H10: =SUMIFS(Issues!$I$2:$I$245,Issues!$D$2:$D$245,A10) | I10: =SUMIFS(Issues!$I$2:$I$245,Issues!$D$2:$D$245,A10,Issues!$L$2:$L$245,"Done") | J10: =IF(H10=0,0,I10/H10) | K10: =COUNTIFS(Issues!$D$2:$D$245,A10,Issues!$J$2:$J$245,"A") | L10: =COUNTIFS(Issues!$D$2:$D$245,A10,Issues!$J$2:$J$245,"A",Issues!$L$2:$L$245,"Done") | M10: =IF(K10=0,0,L10/K10)
A11: financial-engine | B11: =COUNTIFS(Issues!$D$2:$D$245,A11) | C11: =COUNTIFS(Issues!$D$2:$D$245,A11,Issues!$L$2:$L$245,"Done") | D11: =COUNTIFS(Issues!$D$2:$D$245,A11,Issues!$L$2:$L$245,"In Progress") | E11: =COUNTIFS(Issues!$D$2:$D$245,A11,Issues!$L$2:$L$245,"Review") | F11: =B11-C11-D11-E11 | G11: =IF(B11=0,0,C11/B11) | H11: =SUMIFS(Issues!$I$2:$I$245,Issues!$D$2:$D$245,A11) | I11: =SUMIFS(Issues!$I$2:$I$245,Issues!$D$2:$D$245,A11,Issues!$L$2:$L$245,"Done") | J11: =IF(H11=0,0,I11/H11) | K11: =COUNTIFS(Issues!$D$2:$D$245,A11,Issues!$J$2:$J$245,"A") | L11: =COUNTIFS(Issues!$D$2:$D$245,A11,Issues!$J$2:$J$245,"A",Issues!$L$2:$L$245,"Done") | M11: =IF(K11=0,0,L11/K11)
A12: identity | B12: =COUNTIFS(Issues!$D$2:$D$245,A12) | C12: =COUNTIFS(Issues!$D$2:$D$245,A12,Issues!$L$2:$L$245,"Done") | D12: =COUNTIFS(Issues!$D$2:$D$245,A12,Issues!$L$2:$L$245,"In Progress") | E12: =COUNTIFS(Issues!$D$2:$D$245,A12,Issues!$L$2:$L$245,"Review") | F12: =B12-C12-D12-E12 | G12: =IF(B12=0,0,C12/B12) | H12: =SUMIFS(Issues!$I$2:$I$245,Issues!$D$2:$D$245,A12) | I12: =SUMIFS(Issues!$I$2:$I$245,Issues!$D$2:$D$245,A12,Issues!$L$2:$L$245,"Done") | J12: =IF(H12=0,0,I12/H12) | K12: =COUNTIFS(Issues!$D$2:$D$245,A12,Issues!$J$2:$J$245,"A") | L12: =COUNTIFS(Issues!$D$2:$D$245,A12,Issues!$J$2:$J$245,"A",Issues!$L$2:$L$245,"Done") | M12: =IF(K12=0,0,L12/K12)
A13: invoices | B13: =COUNTIFS(Issues!$D$2:$D$245,A13) | C13: =COUNTIFS(Issues!$D$2:$D$245,A13,Issues!$L$2:$L$245,"Done") | D13: =COUNTIFS(Issues!$D$2:$D$245,A13,Issues!$L$2:$L$245,"In Progress") | E13: =COUNTIFS(Issues!$D$2:$D$245,A13,Issues!$L$2:$L$245,"Review") | F13: =B13-C13-D13-E13 | G13: =IF(B13=0,0,C13/B13) | H13: =SUMIFS(Issues!$I$2:$I$245,Issues!$D$2:$D$245,A13) | I13: =SUMIFS(Issues!$I$2:$I$245,Issues!$D$2:$D$245,A13,Issues!$L$2:$L$245,"Done") | J13: =IF(H13=0,0,I13/H13) | K13: =COUNTIFS(Issues!$D$2:$D$245,A13,Issues!$J$2:$J$245,"A") | L13: =COUNTIFS(Issues!$D$2:$D$245,A13,Issues!$J$2:$J$245,"A",Issues!$L$2:$L$245,"Done") | M13: =IF(K13=0,0,L13/K13)
... A21: web | B21: =COUNTIFS(Issues!$D$2:$D$245,A21) | C21: =COUNTIFS(Issues!$D$2:$D$245,A21,Issues!$L$2:$L$245,"Done") | D21: =COUNTIFS(Issues!$D$2:$D$245,A21,Issues!$L$2:$L$245,"In Progress") | E21: =COUNTIFS(Issues!$D$2:$D$245,A21,Issues!$L$2:$L$245,"Review") | F21: =B21-C21-D21-E21 | G21: =IF(B21=0,0,C21/B21) | H21: =SUMIFS(Issues!$I$2:$I$245,Issues!$D$2:$D$245,A21) | I21: =SUMIFS(Issues!$I$2:$I$245,Issues!$D$2:$D$245,A21,Issues!$L$2:$L$245,"Done") | J21: =IF(H21=0,0,I21/H21) | K21: =COUNTIFS(Issues!$D$2:$D$245,A21,Issues!$J$2:$J$245,"A") | L21: =COUNTIFS(Issues!$D$2:$D$245,A21,Issues!$J$2:$J$245,"A",Issues!$L$2:$L$245,"Done") | M21: =IF(K21=0,0,L21/K21)
A22: TOTAL | B22: =SUM(B2:B21) | C22: =SUM(C2:C21) | D22: =SUM(D2:D21) | E22: =SUM(E2:E21) | F22: =SUM(F2:F21) | G22: =IF(B22=0,0,C22/B22) | H22: =SUM(H2:H21) | I22: =SUM(I2:I21) | J22: =IF(H22=0,0,I22/H22) | K22: =SUM(K2:K21) | L22: =SUM(L2:L21) | M22: =IF(K22=0,0,L22/K22)

Sheet Status Summary
A1: Status | B1: All tickets | C1: Cut A | D1: Cut B | E1: M1 | F1: Later
A2: Draft | B2: =COUNTIFS(Issues!$L$2:$L$245,A2) | C2: =COUNTIFS(Issues!$L$2:$L$245,A2,Issues!$J$2:$J$245,"A") | D2: =COUNTIFS(Issues!$L$2:$L$245,A2,Issues!$J$2:$J$245,"B") | E2: =COUNTIFS(Issues!$L$2:$L$245,A2,Issues!$G$2:$G$245,"M1") | F2: =COUNTIFS(Issues!$L$2:$L$245,A2,Issues!$G$2:$G$245,"Later")
A3: Needs Discussion | B3: =COUNTIFS(Issues!$L$2:$L$245,A3) | C3: =COUNTIFS(Issues!$L$2:$L$245,A3,Issues!$J$2:$J$245,"A") | D3: =COUNTIFS(Issues!$L$2:$L$245,A3,Issues!$J$2:$J$245,"B") | E3: =COUNTIFS(Issues!$L$2:$L$245,A3,Issues!$G$2:$G$245,"M1") | F3: =COUNTIFS(Issues!$L$2:$L$245,A3,Issues!$G$2:$G$245,"Later")
A4: Ready for Review | B4: =COUNTIFS(Issues!$L$2:$L$245,A4) | C4: =COUNTIFS(Issues!$L$2:$L$245,A4,Issues!$J$2:$J$245,"A") | D4: =COUNTIFS(Issues!$L$2:$L$245,A4,Issues!$J$2:$J$245,"B") | E4: =COUNTIFS(Issues!$L$2:$L$245,A4,Issues!$G$2:$G$245,"M1") | F4: =COUNTIFS(Issues!$L$2:$L$245,A4,Issues!$G$2:$G$245,"Later")
A5: Accepted | B5: =COUNTIFS(Issues!$L$2:$L$245,A5) | C5: =COUNTIFS(Issues!$L$2:$L$245,A5,Issues!$J$2:$J$245,"A") | D5: =COUNTIFS(Issues!$L$2:$L$245,A5,Issues!$J$2:$J$245,"B") | E5: =COUNTIFS(Issues!$L$2:$L$245,A5,Issues!$G$2:$G$245,"M1") | F5: =COUNTIFS(Issues!$L$2:$L$245,A5,Issues!$G$2:$G$245,"Later")
A6: Ready for Assignment | B6: =COUNTIFS(Issues!$L$2:$L$245,A6) | C6: =COUNTIFS(Issues!$L$2:$L$245,A6,Issues!$J$2:$J$245,"A") | D6: =COUNTIFS(Issues!$L$2:$L$245,A6,Issues!$J$2:$J$245,"B") | E6: =COUNTIFS(Issues!$L$2:$L$245,A6,Issues!$G$2:$G$245,"M1") | F6: =COUNTIFS(Issues!$L$2:$L$245,A6,Issues!$G$2:$G$245,"Later")
A7: Assigned | B7: =COUNTIFS(Issues!$L$2:$L$245,A7) | C7: =COUNTIFS(Issues!$L$2:$L$245,A7,Issues!$J$2:$J$245,"A") | D7: =COUNTIFS(Issues!$L$2:$L$245,A7,Issues!$J$2:$J$245,"B") | E7: =COUNTIFS(Issues!$L$2:$L$245,A7,Issues!$G$2:$G$245,"M1") | F7: =COUNTIFS(Issues!$L$2:$L$245,A7,Issues!$G$2:$G$245,"Later")
A8: In Progress | B8: =COUNTIFS(Issues!$L$2:$L$245,A8) | C8: =COUNTIFS(Issues!$L$2:$L$245,A8,Issues!$J$2:$J$245,"A") | D8: =COUNTIFS(Issues!$L$2:$L$245,A8,Issues!$J$2:$J$245,"B") | E8: =COUNTIFS(Issues!$L$2:$L$245,A8,Issues!$G$2:$G$245,"M1") | F8: =COUNTIFS(Issues!$L$2:$L$245,A8,Issues!$G$2:$G$245,"Later")
A9: Review | B9: =COUNTIFS(Issues!$L$2:$L$245,A9) | C9: =COUNTIFS(Issues!$L$2:$L$245,A9,Issues!$J$2:$J$245,"A") | D9: =COUNTIFS(Issues!$L$2:$L$245,A9,Issues!$J$2:$J$245,"B") | E9: =COUNTIFS(Issues!$L$2:$L$245,A9,Issues!$G$2:$G$245,"M1") | F9: =COUNTIFS(Issues!$L$2:$L$245,A9,Issues!$G$2:$G$245,"Later")
A10: Done | B10: =COUNTIFS(Issues!$L$2:$L$245,A10) | C10: =COUNTIFS(Issues!$L$2:$L$245,A10,Issues!$J$2:$J$245,"A") | D10: =COUNTIFS(Issues!$L$2:$L$245,A10,Issues!$J$2:$J$245,"B") | E10: =COUNTIFS(Issues!$L$2:$L$245,A10,Issues!$G$2:$G$245,"M1") | F10: =COUNTIFS(Issues!$L$2:$L$245,A10,Issues!$G$2:$G$245,"Later")
A11: TOTAL | B11: =SUM(B2:B10) | C11: =SUM(C2:C10) | D11: =SUM(D2:D10) | E11: =SUM(E2:E10) | F11: =SUM(F2:F10)
A13: Generated | B13: 2026-10-11 19:03 | C13: from GitHub Project | D13: https://github.com/users/Nostidus4/projects/1

Sheet Dependencies
A1: Ticket | B1: Blocked by | C1: Ticket status | D1: Blocker status | E1: Blocking now?
A2: ADM-L01 | B2: IDN-006 | C2: =IFERROR(INDEX(Issues!$L$2:$L$245,MATCH(A2,Issues!$A$2:$A$245,0)),"") | D2: =IFERROR(INDEX(Issues!$L$2:$L$245,MATCH(B2,Issues!$A$2:$A$245,0)),"") | E2: =IF(AND(C2<>"Done",D2<>"Done"),"Yes","No")
A3: ADM-L02 | B3: OBS-004 | C3: =IFERROR(INDEX(Issues!$L$2:$L$245,MATCH(A3,Issues!$A$2:$A$245,0)),"") | D3: =IFERROR(INDEX(Issues!$L$2:$L$245,MATCH(B3,Issues!$A$2:$A$245,0)),"") | E3: =IF(AND(C3<>"Done",D3<>"Done"),"Yes","No")
A4: ADM-L03 | B4: ADM-L02 | C4: =IFERROR(INDEX(Issues!$L$2:$L$245,MATCH(A4,Issues!$A$2:$A$245,0)),"") | D4: =IFERROR(INDEX(Issues!$L$2:$L$245,MATCH(B4,Issues!$A$2:$A$245,0)),"") | E4: =IF(AND(C4<>"Done",D4<>"Done"),"Yes","No")
A5: AGT-001 | B5: EXE-002 | C5: =IFERROR(INDEX(Issues!$L$2:$L$245,MATCH(A5,Issues!$A$2:$A$245,0)),"") | D5: =IFERROR(INDEX(Issues!$L$2:$L$245,MATCH(B5,Issues!$A$2:$A$245,0)),"") | E5: =IF(AND(C5<>"Done",D5<>"Done"),"Yes","No")
A6: AGT-002 | B6: AGT-001 | C6: =IFERROR(INDEX(Issues!$L$2:$L$245,MATCH(A6,Issues!$A$2:$A$245,0)),"") | D6: =IFERROR(INDEX(Issues!$L$2:$L$245,MATCH(B6,Issues!$A$2:$A$245,0)),"") | E6: =IF(AND(C6<>"Done",D6<>"Done"),"Yes","No")
A7: AGT-003 | B7: AGT-001 | C7: =IFERROR(INDEX(Issues!$L$2:$L$245,MATCH(A7,Issues!$A$2:$A$245,0)),"") | D7: =IFERROR(INDEX(Issues!$L$2:$L$245,MATCH(B7,Issues!$A$2:$A$245,0)),"") | E7: =IF(AND(C7<>"Done",D7<>"Done"),"Yes","No")
A8: AGT-004 | B8: AGT-003 | C8: =IFERROR(INDEX(Issues!$L$2:$L$245,MATCH(A8,Issues!$A$2:$A$245,0)),"") | D8: =IFERROR(INDEX(Issues!$L$2:$L$245,MATCH(B8,Issues!$A$2:$A$245,0)),"") | E8: =IF(AND(C8<>"Done",D8<>"Done"),"Yes","No")
A9: AGT-004 | B9: AGT-002 | C9: =IFERROR(INDEX(Issues!$L$2:$L$245,MATCH(A9,Issues!$A$2:$A$245,0)),"") | D9: =IFERROR(INDEX(Issues!$L$2:$L$245,MATCH(B9,Issues!$A$2:$A$245,0)),"") | E9: =IF(AND(C9<>"Done",D9<>"Done"),"Yes","No")
A10: AGT-004 | B10: INV-004 | C10: =IFERROR(INDEX(Issues!$L$2:$L$245,MATCH(A10,Issues!$A$2:$A$245,0)),"") | D10: =IFERROR(INDEX(Issues!$L$2:$L$245,MATCH(B10,Issues!$A$2:$A$245,0)),"") | E10: =IF(AND(C10<>"Done",D10<>"Done"),"Yes","No")
A11: AGT-005 | B11: AGT-004 | C11: =IFERROR(INDEX(Issues!$L$2:$L$245,MATCH(A11,Issues!$A$2:$A$245,0)),"") | D11: =IFERROR(INDEX(Issues!$L$2:$L$245,MATCH(B11,Issues!$A$2:$A$245,0)),"") | E11: =IF(AND(C11<>"Done",D11<>"Done"),"Yes","No")
A12: AGT-005 | B12: ENG-005 | C12: =IFERROR(INDEX(Issues!$L$2:$L$245,MATCH(A12,Issues!$A$2:$A$245,0)),"") | D12: =IFERROR(INDEX(Issues!$L$2:$L$245,MATCH(B12,Issues!$A$2:$A$245,0)),"") | E12: =IF(AND(C12<>"Done",D12<>"Done"),"Yes","No")
A13: AGT-006 | B13: AGT-004 | C13: =IFERROR(INDEX(Issues!$L$2:$L$245,MATCH(A13,Issues!$A$2:$A$245,0)),"") | D13: =IFERROR(INDEX(Issues!$L$2:$L$245,MATCH(B13,Issues!$A$2:$A$245,0)),"") | E13: =IF(AND(C13<>"Done",D13<>"Done"),"Yes","No")
... A372: WEB-027 | B372: ENG-014 | C372: =IFERROR(INDEX(Issues!$L$2:$L$245,MATCH(A372,Issues!$A$2:$A$245,0)),"") | D372: =IFERROR(INDEX(Issues!$L$2:$L$245,MATCH(B372,Issues!$A$2:$A$245,0)),"") | E372: =IF(AND(C372<>"Done",D372<>"Done"),"Yes","No")

Sheet How to use
A1: This workbook is a REPORT. GitHub (Project 'TreasuryPilot · Delivery') is the source of truth.
A2: To refresh: uv run --with openpyxl python planning/tracker/build_tracker.py
A3: Do not edit statuses here; change them in the GitHub Project, then rebuild.
A4: Status (column L, Issues) has a dropdown only for quick what-if analysis; changes are not synced back.
A5: Est. days: S = 0.5, M = 1, L = 2 (planning estimates; not re-estimated by developers).
A6: Open blockers = number of tickets listed in 'Blocked by' whose status is not Done.
A7: Cut: A = required for the submission demo, B = stretch, After submission / Later = planned after 20/10.
